Not Found: /
Not Found: /favicon.ico
Not Found: /favicon.ico
Not Found: /
Internal Server Error: /
Traceback (most recent call last):
  File "/usr/local/lib/python2.7/dist-packages/django/core/handlers/base.py", line 114, in get_response
    response = wrapped_callback(request, *callback_args, **callback_kwargs)
TypeError: 'str' object is not callable
Not Found: /
Not Found: /
Internal Server Error: /
Traceback (most recent call last):
  File "/usr/local/lib/python2.7/dist-packages/django/core/handlers/base.py", line 114, in get_response
    response = wrapped_callback(request, *callback_args, **callback_kwargs)
TypeError: 'str' object is not callable
Internal Server Error: /
Traceback (most recent call last):
  File "/usr/local/lib/python2.7/dist-packages/django/core/handlers/base.py", line 114, in get_response
    response = wrapped_callback(request, *callback_args, **callback_kwargs)
TypeError: 'str' object is not callable
Internal Server Error: /
Traceback (most recent call last):
  File "/usr/local/lib/python2.7/dist-packages/django/core/handlers/base.py", line 114, in get_response
    response = wrapped_callback(request, *callback_args, **callback_kwargs)
TypeError: 'str' object is not callable
Internal Server Error: /
Traceback (most recent call last):
  File "/usr/local/lib/python2.7/dist-packages/django/core/handlers/base.py", line 101, in get_response
    resolver_match = resolver.resolve(request.path_info)
  File "/usr/local/lib/python2.7/dist-packages/django/core/urlresolvers.py", line 320, in resolve
    sub_match = pattern.resolve(new_path)
  File "/usr/local/lib/python2.7/dist-packages/django/core/urlresolvers.py", line 222, in resolve
    return ResolverMatch(self.callback, args, kwargs, self.name)
  File "/usr/local/lib/python2.7/dist-packages/django/core/urlresolvers.py", line 229, in callback
    self._callback = get_callable(self._callback_str)
  File "/usr/local/lib/python2.7/dist-packages/django/utils/functional.py", line 32, in wrapper
    result = func(*args)
  File "/usr/local/lib/python2.7/dist-packages/django/core/urlresolvers.py", line 96, in get_callable
    mod = import_module(mod_name)
  File "/usr/local/lib/python2.7/dist-packages/django/utils/importlib.py", line 40, in import_module
    __import__(name)
ImportError: No module named views
Internal Server Error: /
Traceback (most recent call last):
  File "/usr/local/lib/python2.7/dist-packages/django/core/handlers/base.py", line 114, in get_response
    response = wrapped_callback(request, *callback_args, **callback_kwargs)
  File "/var/www/html/laboratorio/teste-planetkids/teste/blog/views.py", line 30, in home
    return render_to_response('blog/index.html',locals(),context_instance=RequestContext(request),)
  File "/usr/local/lib/python2.7/dist-packages/django/shortcuts/__init__.py", line 29, in render_to_response
    return HttpResponse(loader.render_to_string(*args, **kwargs), **httpresponse_kwargs)
  File "/usr/local/lib/python2.7/dist-packages/django/template/loader.py", line 169, in render_to_string
    return t.render(context_instance)
  File "/usr/local/lib/python2.7/dist-packages/django/template/base.py", line 140, in render
    return self._render(context)
  File "/usr/local/lib/python2.7/dist-packages/django/template/base.py", line 134, in _render
    return self.nodelist.render(context)
  File "/usr/local/lib/python2.7/dist-packages/django/template/base.py", line 840, in render
    bit = self.render_node(node, context)
  File "/usr/local/lib/python2.7/dist-packages/django/template/debug.py", line 78, in render_node
    return node.render(context)
  File "/usr/local/lib/python2.7/dist-packages/django/template/loader_tags.py", line 123, in render
    return compiled_parent._render(context)
  File "/usr/local/lib/python2.7/dist-packages/django/template/base.py", line 134, in _render
    return self.nodelist.render(context)
  File "/usr/local/lib/python2.7/dist-packages/django/template/base.py", line 840, in render
    bit = self.render_node(node, context)
  File "/usr/local/lib/python2.7/dist-packages/django/template/debug.py", line 78, in render_node
    return node.render(context)
  File "/usr/local/lib/python2.7/dist-packages/django/template/defaulttags.py", line 447, in render
    six.reraise(*exc_info)
  File "/usr/local/lib/python2.7/dist-packages/django/template/defaulttags.py", line 433, in render
    url = reverse(view_name, args=args, kwargs=kwargs, current_app=context.current_app)
  File "/usr/local/lib/python2.7/dist-packages/django/core/urlresolvers.py", line 509, in reverse
    return iri_to_uri(resolver._reverse_with_prefix(view, prefix, *args, **kwargs))
  File "/usr/local/lib/python2.7/dist-packages/django/core/urlresolvers.py", line 429, in _reverse_with_prefix
    (lookup_view_s, args, kwargs, len(patterns), patterns))
NoReverseMatch: Reverse for 'home_index' with arguments '()' and keyword arguments '{}' not found. 0 pattern(s) tried: []
Internal Server Error: /blog/cadastro-usuario/
Traceback (most recent call last):
  File "/usr/local/lib/python2.7/dist-packages/django/core/handlers/base.py", line 101, in get_response
    resolver_match = resolver.resolve(request.path_info)
  File "/usr/local/lib/python2.7/dist-packages/django/core/urlresolvers.py", line 320, in resolve
    sub_match = pattern.resolve(new_path)
  File "/usr/local/lib/python2.7/dist-packages/django/core/urlresolvers.py", line 320, in resolve
    sub_match = pattern.resolve(new_path)
  File "/usr/local/lib/python2.7/dist-packages/django/core/urlresolvers.py", line 222, in resolve
    return ResolverMatch(self.callback, args, kwargs, self.name)
  File "/usr/local/lib/python2.7/dist-packages/django/core/urlresolvers.py", line 229, in callback
    self._callback = get_callable(self._callback_str)
  File "/usr/local/lib/python2.7/dist-packages/django/utils/functional.py", line 32, in wrapper
    result = func(*args)
  File "/usr/local/lib/python2.7/dist-packages/django/core/urlresolvers.py", line 96, in get_callable
    mod = import_module(mod_name)
  File "/usr/local/lib/python2.7/dist-packages/django/utils/importlib.py", line 40, in import_module
    __import__(name)
  File "/var/www/html/laboratorio/teste-planetkids/teste/blog/views.py", line 23, in <module>
    from django.shortcuts   import render_to_response,reverse
ImportError: cannot import name reverse
Internal Server Error: /blog/cadastro-usuario/
Traceback (most recent call last):
  File "/usr/local/lib/python2.7/dist-packages/django/core/handlers/base.py", line 114, in get_response
    response = wrapped_callback(request, *callback_args, **callback_kwargs)
  File "/var/www/html/laboratorio/teste-planetkids/teste/blog/views.py", line 42, in usuario
    if form.is_valid():
UnboundLocalError: local variable 'form' referenced before assignment
Internal Server Error: /blog/cadastro-usuario/
Traceback (most recent call last):
  File "/usr/local/lib/python2.7/dist-packages/django/core/handlers/base.py", line 114, in get_response
    response = wrapped_callback(request, *callback_args, **callback_kwargs)
  File "/var/www/html/laboratorio/teste-planetkids/teste/blog/views.py", line 43, in usuario
    novo_usuario = form.save()
  File "/var/www/html/laboratorio/teste-planetkids/teste/blog/forms.py", line 48, in save
    usuario = super(FormRegistro, self).save(commit=False)
NameError: global name 'FormRegistro' is not defined
Internal Server Error: /blog/cadastro-usuario/
Traceback (most recent call last):
  File "/usr/local/lib/python2.7/dist-packages/django/core/handlers/base.py", line 101, in get_response
    resolver_match = resolver.resolve(request.path_info)
  File "/usr/local/lib/python2.7/dist-packages/django/core/urlresolvers.py", line 320, in resolve
    sub_match = pattern.resolve(new_path)
  File "/usr/local/lib/python2.7/dist-packages/django/core/urlresolvers.py", line 320, in resolve
    sub_match = pattern.resolve(new_path)
  File "/usr/local/lib/python2.7/dist-packages/django/core/urlresolvers.py", line 222, in resolve
    return ResolverMatch(self.callback, args, kwargs, self.name)
  File "/usr/local/lib/python2.7/dist-packages/django/core/urlresolvers.py", line 229, in callback
    self._callback = get_callable(self._callback_str)
  File "/usr/local/lib/python2.7/dist-packages/django/utils/functional.py", line 32, in wrapper
    result = func(*args)
  File "/usr/local/lib/python2.7/dist-packages/django/core/urlresolvers.py", line 96, in get_callable
    mod = import_module(mod_name)
  File "/usr/local/lib/python2.7/dist-packages/django/utils/importlib.py", line 40, in import_module
    __import__(name)
  File "/var/www/html/laboratorio/teste-planetkids/teste/blog/views.py", line 28, in <module>
    from forms      import FormUser
  File "/var/www/html/laboratorio/teste-planetkids/teste/blog/forms.py", line 25, in <module>
    class FormUser(forms.ModelForm):
  File "/var/www/html/laboratorio/teste-planetkids/teste/blog/forms.py", line 31, in FormUser
    first_name       = forms.CharField(unique=True,)
  File "/usr/local/lib/python2.7/dist-packages/django/forms/fields.py", line 198, in __init__
    super(CharField, self).__init__(*args, **kwargs)
TypeError: __init__() got an unexpected keyword argument 'unique'
Internal Server Error: /blog/cadastro-usuario/
Traceback (most recent call last):
  File "/usr/local/lib/python2.7/dist-packages/django/core/handlers/base.py", line 114, in get_response
    response = wrapped_callback(request, *callback_args, **callback_kwargs)
  File "/var/www/html/laboratorio/teste-planetkids/teste/blog/views.py", line 48, in usuario
    return render_to_response('blog/usuario.html',locals(),context_instance=RequestContext(request),)
  File "/usr/local/lib/python2.7/dist-packages/django/shortcuts/__init__.py", line 29, in render_to_response
    return HttpResponse(loader.render_to_string(*args, **kwargs), **httpresponse_kwargs)
  File "/usr/local/lib/python2.7/dist-packages/django/template/loader.py", line 169, in render_to_string
    return t.render(context_instance)
  File "/usr/local/lib/python2.7/dist-packages/django/template/base.py", line 140, in render
    return self._render(context)
  File "/usr/local/lib/python2.7/dist-packages/django/template/base.py", line 134, in _render
    return self.nodelist.render(context)
  File "/usr/local/lib/python2.7/dist-packages/django/template/base.py", line 840, in render
    bit = self.render_node(node, context)
  File "/usr/local/lib/python2.7/dist-packages/django/template/debug.py", line 78, in render_node
    return node.render(context)
  File "/usr/local/lib/python2.7/dist-packages/django/template/loader_tags.py", line 101, in render
    compiled_parent = self.get_parent(context)
  File "/usr/local/lib/python2.7/dist-packages/django/template/loader_tags.py", line 98, in get_parent
    return get_template(parent)
  File "/usr/local/lib/python2.7/dist-packages/django/template/loader.py", line 138, in get_template
    template, origin = find_template(template_name)
  File "/usr/local/lib/python2.7/dist-packages/django/template/loader.py", line 127, in find_template
    source, display_name = loader(name, dirs)
  File "/usr/local/lib/python2.7/dist-packages/django/template/loader.py", line 43, in __call__
    return self.load_template(template_name, template_dirs)
  File "/usr/local/lib/python2.7/dist-packages/django/template/loader.py", line 49, in load_template
    template = get_template_from_string(source, origin, template_name)
  File "/usr/local/lib/python2.7/dist-packages/django/template/loader.py", line 149, in get_template_from_string
    return Template(source, origin, name)
  File "/usr/local/lib/python2.7/dist-packages/django/template/base.py", line 125, in __init__
    self.nodelist = compile_string(template_string, origin)
  File "/usr/local/lib/python2.7/dist-packages/django/template/base.py", line 153, in compile_string
    return parser.parse()
  File "/usr/local/lib/python2.7/dist-packages/django/template/base.py", line 278, in parse
    compiled_result = compile_func(self, token)
  File "/usr/local/lib/python2.7/dist-packages/django/template/defaulttags.py", line 942, in do_if
    nodelist = parser.parse(('elif', 'else', 'endif'))
  File "/usr/local/lib/python2.7/dist-packages/django/template/base.py", line 254, in parse
    filter_expression = self.compile_filter(token.contents)
  File "/usr/local/lib/python2.7/dist-packages/django/template/base.py", line 360, in compile_filter
    return FilterExpression(token, self)
  File "/usr/local/lib/python2.7/dist-packages/django/template/base.py", line 577, in __init__
    "from '%s'" % (token[upto:], token))
TemplateSyntaxError: Could not parse the remainder: '"D/M/Y"' from 'user.date_joined|date"D/M/Y"'
Internal Server Error: /blog/cadastro-usuario/
Traceback (most recent call last):
  File "/usr/local/lib/python2.7/dist-packages/django/core/handlers/base.py", line 114, in get_response
    response = wrapped_callback(request, *callback_args, **callback_kwargs)
  File "/var/www/html/laboratorio/teste-planetkids/teste/blog/views.py", line 48, in usuario
    return render_to_response('blog/usuario.html',locals(),context_instance=RequestContext(request),)
  File "/usr/local/lib/python2.7/dist-packages/django/shortcuts/__init__.py", line 29, in render_to_response
    return HttpResponse(loader.render_to_string(*args, **kwargs), **httpresponse_kwargs)
  File "/usr/local/lib/python2.7/dist-packages/django/template/loader.py", line 169, in render_to_string
    return t.render(context_instance)
  File "/usr/local/lib/python2.7/dist-packages/django/template/base.py", line 140, in render
    return self._render(context)
  File "/usr/local/lib/python2.7/dist-packages/django/template/base.py", line 134, in _render
    return self.nodelist.render(context)
  File "/usr/local/lib/python2.7/dist-packages/django/template/base.py", line 840, in render
    bit = self.render_node(node, context)
  File "/usr/local/lib/python2.7/dist-packages/django/template/debug.py", line 78, in render_node
    return node.render(context)
  File "/usr/local/lib/python2.7/dist-packages/django/template/loader_tags.py", line 101, in render
    compiled_parent = self.get_parent(context)
  File "/usr/local/lib/python2.7/dist-packages/django/template/loader_tags.py", line 98, in get_parent
    return get_template(parent)
  File "/usr/local/lib/python2.7/dist-packages/django/template/loader.py", line 138, in get_template
    template, origin = find_template(template_name)
  File "/usr/local/lib/python2.7/dist-packages/django/template/loader.py", line 127, in find_template
    source, display_name = loader(name, dirs)
  File "/usr/local/lib/python2.7/dist-packages/django/template/loader.py", line 43, in __call__
    return self.load_template(template_name, template_dirs)
  File "/usr/local/lib/python2.7/dist-packages/django/template/loader.py", line 49, in load_template
    template = get_template_from_string(source, origin, template_name)
  File "/usr/local/lib/python2.7/dist-packages/django/template/loader.py", line 149, in get_template_from_string
    return Template(source, origin, name)
  File "/usr/local/lib/python2.7/dist-packages/django/template/base.py", line 125, in __init__
    self.nodelist = compile_string(template_string, origin)
  File "/usr/local/lib/python2.7/dist-packages/django/template/base.py", line 153, in compile_string
    return parser.parse()
  File "/usr/local/lib/python2.7/dist-packages/django/template/base.py", line 278, in parse
    compiled_result = compile_func(self, token)
  File "/usr/local/lib/python2.7/dist-packages/django/template/defaulttags.py", line 942, in do_if
    nodelist = parser.parse(('elif', 'else', 'endif'))
  File "/usr/local/lib/python2.7/dist-packages/django/template/base.py", line 254, in parse
    filter_expression = self.compile_filter(token.contents)
  File "/usr/local/lib/python2.7/dist-packages/django/template/base.py", line 360, in compile_filter
    return FilterExpression(token, self)
  File "/usr/local/lib/python2.7/dist-packages/django/template/base.py", line 577, in __init__
    "from '%s'" % (token[upto:], token))
TemplateSyntaxError: Could not parse the remainder: ''D/M/Y'' from 'user.date_joined|date'D/M/Y''
Internal Server Error: /blog/cadastro-usuario/
Traceback (most recent call last):
  File "/usr/local/lib/python2.7/dist-packages/django/core/handlers/base.py", line 114, in get_response
    response = wrapped_callback(request, *callback_args, **callback_kwargs)
  File "/var/www/html/laboratorio/teste-planetkids/teste/blog/views.py", line 45, in usuario
    usuario = User.objects.get(email=novo_usuario.cleaned_data['email'])
NameError: global name 'User' is not defined
Internal Server Error: /blog/cadastro-usuario/
Traceback (most recent call last):
  File "/usr/local/lib/python2.7/dist-packages/django/core/handlers/base.py", line 114, in get_response
    response = wrapped_callback(request, *callback_args, **callback_kwargs)
  File "/var/www/html/laboratorio/teste-planetkids/teste/blog/views.py", line 46, in usuario
    usuario = User.objects.get(email=novo_usuario.cleaned_data['email'])
AttributeError: 'User' object has no attribute 'cleaned_data'
Not Found: /sair/
Internal Server Error: /
Traceback (most recent call last):
  File "/usr/local/lib/python2.7/dist-packages/django/core/handlers/base.py", line 114, in get_response
    response = wrapped_callback(request, *callback_args, **callback_kwargs)
  File "/var/www/html/laboratorio/teste-planetkids/teste/blog/views.py", line 36, in home
    posts = Post.object.all()
AttributeError: type object 'Post' has no attribute 'object'
Not Found: /favicon.ico
Not Found: /favicon.ico
